<?xml version="1.0"?>

<robot name = "andarilho">

  <link name="tronco_link">
    <visual>
      <origin xyz = "0 0 2.2" rpy="0 0 0"/>
      <geometry>
        <box size ="0.22 0.9 1" />
      </geometry>
      <material name="green">
        <color rgba="0 1 0 0.5"/>
      </material>
    </visual>
    <collision>
      <origin xyz = "0 0 2.2" rpy="0 0 0"/>
      <geometry>
        <box size ="0.22 0.9 1" />
      </geometry>
    </collision>
    <inertial>
      <origin xyz ="0 0 2.2" rpy="0 0 0"/>
      <mass value="4" />
      <inertia ixx="0.0" ixy ="0.0" ixz ="0.0" iyy="0.0" iyz="0.0" izz="0.0"/>
    </inertial>
  </link>

  <gazebo reference="tronco_link">
    <material>Gazebo/Green</material>
  </gazebo>


  <joint name="sensor_esq_joint" type="fixed">
    <origin xyz ="0.11 0.3 2.6" rpy = "0 0 0"/>
    <parent link="tronco_link"/>
    <child link="sensor_esq_link"/>
  </joint>

  <link name="sensor_esq_link">
    <visual>
      <origin xyz = "0 0 0" rpy="0 0 0"/>
      <geometry>
        <box size ="0.1 0.2 0.1" />
      </geometry>
      <material name="color1">
        <color rgba="1 0 0 0.5"/>
      </material>
    </visual>
    <collision>
      <origin xyz = "0 0 0" rpy="0 0 0"/>
      <geometry>
        <box size ="0.1 0.2 0.1" />
      </geometry>
    </collision>
  </link>

  <gazebo reference="sensor_esq_link">
    <gravity>true</gravity>
    <sensor name="sensor_esq" type="imu">
      <always_on>true</always_on>
      <update_rate>40</update_rate>
      <visualize>true</visualize>
      <topic>sensor_esq_topic</topic>
      <plugin filename="libgazebo_ros_imu_sensor.so" name="imu_plugin1">
        <topicName>sensor_esq_topic</topicName>
        <bodyName>sensor_esq_link</bodyName>
        <updateRateHZ>40.0</updateRateHZ>
        <gaussianNoise>0.0</gaussianNoise>
        <xyzOffset>0 0 0</xyzOffset>
        <rpyOffset>0 0 0</rpyOffset>
        <frameName>sensor_esq_link</frameName>
        <initialOrientationAsReference>false</initialOrientationAsReference>
      </plugin>
      <pose>0 0 0 0 0 0</pose>
    </sensor>
  </gazebo>

  <joint name="sensor_dir_joint" type="fixed">
    <origin xyz ="0.11 -0.3 2.6" rpy = "0 0 0"/>
    <parent link="tronco_link"/>
    <child link="sensor_dir_link"/>
  </joint>

  <link name="sensor_dir_link">
    <visual>
      <origin xyz = "0 0 0" rpy="0 0 0"/>
      <geometry>
        <box size ="0.1 0.2 0.1" />
      </geometry>
      <material name="color1">
        <color rgba="1 0 0 0.5"/>
      </material>
    </visual>
    <collision>
      <origin xyz = "0 0 0" rpy="0 0 0"/>
      <geometry>
        <box size ="0.1 0.2 0.1" />
      </geometry>
    </collision>
  </link>

  <gazebo reference="sensor_dir_link">
    <gravity>true</gravity>
    <sensor name="sensor_dir" type="imu">
      <always_on>true</always_on>
      <update_rate>40</update_rate>
      <visualize>true</visualize>
      <topic>sensor_dir_topic</topic>
      <plugin filename="libgazebo_ros_imu_sensor.so" name="imu_plugin2">
        <topicName>sensor_dir_topic</topicName>
        <bodyName>sensor_dir_link</bodyName>
        <updateRateHZ>40.0</updateRateHZ>
        <gaussianNoise>0.0</gaussianNoise>
        <xyzOffset>0 0 0</xyzOffset>
        <rpyOffset>0 0 0</rpyOffset>
        <frameName>sensor_dir_link</frameName>
        <initialOrientationAsReference>false</initialOrientationAsReference>
      </plugin>
      <pose>0 0 0 0 0 0</pose>
    </sensor>
  </gazebo>


  <joint name="quadril_esq_x_joint" type="revolute">
    <origin xyz="0 0.38 1.7" rpy="0 0 0"/>
    <parent link="tronco_link"/>
    <child link ="quad_esq_link"/>
    <axis xyz = "0 1 0"/>
    <limit lower="-1.57" upper="1.57" velocity="1" effort="1"/>
    <dynamics damping="10.0" friction="100.0"/>
  </joint>

  <link name="quad_esq_link">
    <visual>
      <origin xyz = "0 -0.125 -0.1" rpy="0 0 0"/>
      <geometry>
        <box size ="0.22 0.25 0.2" />
      </geometry>
      <material name="color1">
        <color rgba="1 0 0 0.5"/>
      </material>
    </visual>
    <collision>
      <origin xyz = "0 -0.125 -0.1" rpy="0 0 0"/>
      <geometry>
        <box size ="0.22 0.25 0.2" />
      </geometry>
    </collision>
    <inertial>
      <origin xyz ="0 -0.125 -0.1" rpy="0 0 0"/>
      <mass value="1" />
      <inertia ixx="0.0" ixy ="0.0" ixz ="0.0" iyy="0.0" iyz="0.0" izz="0.0"/>
    </inertial>
  </link>

  <gazebo reference="quad_esq_link">
    <material>Gazebo/Red</material>
  </gazebo>

  <joint name="quadril_esq_y_joint" type="revolute">
    <origin xyz="0 0 -0.2" rpy="0 0 0"/>
    <parent link="quad_esq_link"/>
    <child link ="perna1_esq_link"/>
    <axis xyz = "1 0 0"/>
    <limit lower="-1.57" upper="1.57" velocity="1" effort="1"/>
    <dynamics damping="10.0" friction="100.0"/>
  </joint>


  <link name="perna1_esq_link">
    <visual>
      <origin xyz = "0 -0.125 -0.35" rpy="0 0 0"/>
      <geometry>
        <box size ="0.22 0.25 0.7" />
      </geometry>
      <material name="color1">
        <color rgba="1 0 0 0.5"/>
      </material>
    </visual>
    <collision>
      <origin xyz = "0 -0.125 -0.35" rpy="0 0 0"/>
      <geometry>
        <box size ="0.22 0.25 0.7" />
      </geometry>
    </collision>
    <inertial>
      <origin xyz ="0 -0.125 -0.35" rpy="0 0 0"/>
      <mass value="2" />
      <inertia ixx="0.0" ixy ="0.0" ixz ="0.0" iyy="0.0" iyz="0.0" izz="0.0"/>
    </inertial>
  </link>

  <gazebo reference="perna1_esq_link">
    <material>Gazebo/Red</material>
  </gazebo>

  <joint name="quadril_dir_x_joint" type="revolute">
    <origin xyz="0 -0.38 1.7" rpy="0 0 0"/>
    <parent link="tronco_link"/>
    <child link ="quad_dir_link"/>
    <axis xyz = "0 1 0"/>
    <limit lower="-1.57" upper="1.57" velocity="1" effort="1"/>
    <dynamics damping="10.0" friction="100.0"/>
  </joint>

    <link name="quad_dir_link">
    <visual>
      <origin xyz = "0 0.125 -0.1" rpy="0 0 0"/>
      <geometry>
        <box size ="0.22 0.25 0.2" />
      </geometry>
      <material name="color1">
        <color rgba="1 0 0 0.5"/>
      </material>
    </visual>
    <collision>
      <origin xyz = "0 0.125 -0.1" rpy="0 0 0"/>
      <geometry>
        <box size ="0.22 0.25 0.2" />
      </geometry>
    </collision>
    <inertial>
      <origin xyz ="0 0.125 -0.1" rpy="0 0 0"/>
      <mass value="1" />
      <inertia ixx="0.0" ixy ="0.0" ixz ="0.0" iyy="0.0" iyz="0.0" izz="0.0"/>
    </inertial>
  </link>

  <gazebo reference="quad_dir_link">
    <material>Gazebo/Red</material>
  </gazebo>

  <joint name="quadril_dir_y_joint" type="revolute">
    <origin xyz="0 0 -0.2" rpy="0 0 0"/>
    <parent link="quad_dir_link"/>
    <child link ="perna1_dir_link"/>
    <axis xyz = "1 0 0"/>
    <limit lower="-1.57" upper="1.57" velocity="1" effort="1"/>
    <dynamics damping="10.0" friction="100.0"/>
  </joint>

  <link name="perna1_dir_link">
    <visual>
      <origin xyz = "0 0.125 -0.35" rpy="0 0 0"/>
      <geometry>
        <box size ="0.22 0.25 0.7" />
      </geometry>
      <material name="color1">
        <color rgba="1 0 0 0.5"/>
      </material>
    </visual>
    <collision>
      <origin xyz = "0 0.125 -0.35" rpy="0 0 0"/>
      <geometry>
        <box size ="0.22 0.25 0.7" />
      </geometry>
    </collision>
    <inertial>
      <origin xyz ="0 0.125 -0.35" rpy="0 0 0"/>
      <mass value="2" />
      <inertia ixx="0.0" ixy ="0.0" ixz ="0.0" iyy="0.0" iyz="0.0" izz="0.0"/>
    </inertial>
  </link>

  <gazebo reference="perna1_dir_link">
    <material>Gazebo/Red</material>
  </gazebo>

  <joint name="joelho_esq_joint" type="revolute">
    <origin xyz="0 0 -0.7" rpy="0 0 0"/>
    <parent link="perna1_esq_link"/>
    <child link ="perna2_esq_link"/>
    <axis xyz = "0 1 0"/>
    <limit lower="-3" upper="3" velocity="1" effort="1"/>
    <dynamics damping="10.0" friction="100.0"/>
  </joint>

  <link name="perna2_esq_link">
    <visual>
      <origin xyz = "0 -0.125 -0.35" rpy="0 0 0"/>
      <geometry>
        <box size ="0.22 0.25 0.7" />
      </geometry>
      <material name="color2">
        <color rgba="0 0 1 0.5"/>
      </material>
    </visual>
    <collision>
      <origin xyz = "0 -0.125 -0.35" rpy="0 0 0"/>
      <geometry>
        <box size ="0.22 0.25 0.7" />
      </geometry>
    </collision>
    <inertial>
      <origin xyz ="0 -0.125 -0.35" rpy="0 0 0"/>
      <mass value="2" />
      <inertia ixx="0.0" ixy ="0.0" ixz ="0.0" iyy="0.0" iyz="0.0" izz="0.0"/>
    </inertial>
  </link>

  <gazebo reference="perna2_esq_link">
    <material>Gazebo/Blue</material>
  </gazebo>

  <joint name="joelho_dir_joint" type="revolute">
    <origin xyz="0 0 -0.7" rpy="0 0 0"/>
    <parent link="perna1_dir_link"/>
    <child link ="perna2_dir_link"/>
    <axis xyz = "0 1 0"/>
    <limit lower="-3" upper="3" velocity="1" effort="1"/>
    <dynamics damping="10.0" friction="100.0"/>
  </joint>

  <link name="perna2_dir_link">
    <visual>
      <origin xyz = "0 0.125 -0.35" rpy="0 0 0"/>
      <geometry>
        <box size ="0.22 0.25 0.7" />
      </geometry>
      <material name="color2">
        <color rgba="0 0 1 0.5"/>
      </material>
    </visual>
    <collision>
      <origin xyz = "0 0.125 -0.35" rpy="0 0 0"/>
      <geometry>
        <box size ="0.22 0.25 0.7" />
      </geometry>
    </collision>
    <inertial>
      <origin xyz ="0 0.125 -0.35" rpy="0 0 0"/>
      <mass value="2" />
      <inertia ixx="0.0" ixy ="0.0" ixz ="0.0" iyy="0.0" iyz="0.0" izz="0.0"/>
    </inertial>
  </link>

  <gazebo reference="perna2_dir_link">
    <material>Gazebo/Blue</material>
  </gazebo>

  <joint name="torn_esq_joint" type="revolute">
    <origin xyz="0 0 -0.7" rpy="0 0 0"/>
    <parent link="perna2_esq_link"/>
    <child link ="pe_esq_link"/>
    <axis xyz = "0 1 0"/>
    <limit lower="-1.57" upper="1.57" velocity="1" effort="1"/>
    <dynamics damping="10.0" friction="100.0"/>
  </joint>

  <link name="pe_esq_link">
    <visual>
      <origin xyz = "0.1 -0.125 -0.05" rpy="0 0 0"/>
      <geometry>
        <box size ="0.5 0.4 0.1" />
      </geometry>
      <material name="color3">
        <color rgba="0 0 0 0.5"/>
      </material>
    </visual>
    <collision>
      <origin xyz = "0.1 -0.125 -0.05" rpy="0 0 0"/>
      <geometry>
        <box size ="0.5 0.4 0.1" />
      </geometry>
      <surface>
        <contact>
          <ode>
            <kp>1.0</kp>
            <kd>0.01</kd>
            <max_vel>0.0</max_vel>
            <min_depth>0.001</min_depth>
          </ode>
        </contact>
        <friction>
          <ode>
            <mu>100.0</mu>
            <mu2>100.0</mu2>
          </ode>
        </friction>
      </surface>
    </collision>
    <inertial>
      <origin xyz ="0.1 -0.125 -0.05" rpy="0 0 0"/>
      <mass value="10" />
      <inertia ixx="0.0" ixy ="0.0" ixz ="0.0" iyy="0.0" iyz="0.0" izz="0.0"/>
    </inertial>
  </link>

  <gazebo reference="pe_esq_link">
    <material>Gazebo/Black</material>
  </gazebo>

  <joint name="torn_dir_joint" type="revolute">
    <origin xyz="0 0 -0.7" rpy="0 0 0"/>
    <parent link="perna2_dir_link"/>
    <child link ="pe_dir_link"/>
    <axis xyz = "0 1 0"/>
    <limit lower="-1.57" upper="1.57" velocity="1" effort="1"/>
    <dynamics damping="10.0" friction="100.0"/>
  </joint>

  <link name="pe_dir_link">
    <visual>
      <origin xyz = "0.1 0.125 -0.05" rpy="0 0 0"/>
      <geometry>
        <box size ="0.5 0.4 0.1" />
      </geometry>
      <material name="color3">
        <color rgba="0 0 0 0.5"/>
      </material>
    </visual>
    <collision>
      <origin xyz = "0.1 0.125 -0.05" rpy="0 0 0"/>
      <geometry>
        <box size ="0.5 0.4 0.1" />
      </geometry>
      <surface>
        <contact>
          <ode>
            <kp>1.0</kp>
            <kd>0.01</kd>
            <max_vel>0.0</max_vel>
            <min_depth>0.001</min_depth>
          </ode>
        </contact>
        <friction>
          <mu>100.0</mu>
          <mu2>100.0</mu2>
        </friction>
      </surface>
    </collision>
    <inertial>
      <origin xyz ="0.1 0.125 -0.05" rpy="0 0 0"/>
      <mass value="10" />
      <inertia ixx="0.0" ixy ="0.0" ixz ="0.0" iyy="0.0" iyz="0.0" izz="0.0"/>
    </inertial>
  </link>

  <gazebo reference="pe_dir_link">
    <material>Gazebo/Black</material>
  </gazebo>

  <gazebo>
    <plugin name="gazebo_ros_joint_state_publisher" 
        filename="gazebo_ros_joint_state_publisher.so">
        <updateRate>40</updateRate>
        <jointName>quadril_dir_x_joint</jointName>
        <jointName>quadril_dir_y_joint</jointName>
        <jointName>quadril_esq_x_joint</jointName>
        <jointName>quadril_esq_y_joint</jointName>
        <jointName>joelho_dir_joint</jointName>
        <jointName>joelho_esq_joint</jointName>
        <jointName>torn_dir_joint</jointName>
        <jointName>torn_esq_joint</jointName>
    </plugin>
  </gazebo>

  <gazebo>
    <plugin name="gazebo_ros_joint_pose_trajectory" 
        filename="libgazebo_ros_joint_pose_trajectory.so">
        <updateRate>40</updateRate>
    </plugin>

  </gazebo>
  
</robot>